<?xml version="1.0" ?>
<!-- =================================================================================== -->
<!-- |    This document was autogenerated by xacro from src/my_robot/urdf/my_robot.urdf.xacro | -->
<!-- |    EDITING THIS FILE BY HAND IS NOT RECOMMENDED                                 | -->
<!-- =================================================================================== -->
<robot name="my_robot">
  <link name="base_link">
    <inertial>
      <origin rpy="0 0 0" xyz="0 0 .3"/>
      <mass value="58.7"/>
      <inertia ixx="0.166667" ixy="0" ixz="0" iyy="0.166667" iyz="0" izz="0.166667"/>
    </inertial>
    <visual>
      <origin rpy="0 0 0" xyz="0 0 .3"/>
      <geometry>
        <box size="0.5 0.95 0.5"/>
      </geometry>
      <material name="gray">
        <color rgba="0.7 0.7 0.7 1"/>
      </material>
    </visual>
    <collision>
      <origin rpy="0 0 0" xyz="0 0 .3"/>
      <geometry>
        <box size="0.95 0.5 0.5"/>
      </geometry>
    </collision>
  </link>
  <link name="wheel_link_front_left">
    <inertial>
      <origin rpy="1.5708 0 0" xyz="0 0 0"/>
      <mass value="1.0"/>
      <inertia ixx="0.001" ixy="0" ixz="0" iyy="0.001" iyz="0" izz="0.001"/>
    </inertial>
    <visual>
      <origin rpy="1.5708 0 0" xyz="0 0 0"/>
      <geometry>
        <cylinder length="0.11" radius="0.125"/>
      </geometry>
      <material name="gray">
        <color rgba="0.5 0.5 0.5 1"/>
      </material>
    </visual>
    <collision>
      <origin rpy="1.5708 0 0" xyz="0 0 0"/>
      <geometry>
        <cylinder length="0.11" radius="0.125"/>
      </geometry>
    </collision>
  </link>
  <link name="wheel_link_front_right">
    <inertial>
      <origin rpy="1.5708 0 0" xyz="0 0 0"/>
      <mass value="1.0"/>
      <inertia ixx="0.001" ixy="0" ixz="0" iyy="0.001" iyz="0" izz="0.001"/>
    </inertial>
    <visual>
      <origin rpy="1.5708 0 0" xyz="0 0 0"/>
      <geometry>
        <cylinder length="0.11" radius="0.125"/>
      </geometry>
      <material name="gray">
        <color rgba="0.5 0.5 0.5 1"/>
      </material>
    </visual>
    <collision>
      <origin rpy="1.5708 0 0" xyz="0 0 0"/>
      <geometry>
        <cylinder length="0.11" radius="0.125"/>
      </geometry>
    </collision>
  </link>
  <link name="wheel_link_back_left">
    <inertial>
      <origin rpy="1.5708 0 0" xyz="0 0 0"/>
      <mass value="1.0"/>
      <inertia ixx="0.001" ixy="0" ixz="0" iyy="0.001" iyz="0" izz="0.001"/>
    </inertial>
    <visual>
      <origin rpy="1.5708 0 0" xyz="0 0 0"/>
      <geometry>
        <cylinder length="0.11" radius="0.125"/>
      </geometry>
      <material name="gray">
        <color rgba="0.5 0.5 0.5 1"/>
      </material>
    </visual>
    <collision>
      <origin rpy="1.5708 0 0" xyz="0 0 0"/>
      <geometry>
        <cylinder length="0.11" radius="0.125"/>
      </geometry>
    </collision>
  </link>
  <link name="wheel_link_back_right">
    <inertial>
      <origin rpy="1.5708 0 0" xyz="0 0 0"/>
      <mass value="1.0"/>
      <inertia ixx="0.001" ixy="0" ixz="0" iyy="0.001" iyz="0" izz="0.001"/>
    </inertial>
    <visual>
      <origin rpy="1.5708 0 0" xyz="0 0 0"/>
      <geometry>
        <cylinder length="0.11" radius="0.125"/>
      </geometry>
      <material name="gray">
        <color rgba="0.5 0.5 0.5 1"/>
      </material>
    </visual>
    <collision>
      <origin rpy="1.5708 0 0" xyz="0 0 0"/>
      <geometry>
        <cylinder length="0.11" radius="0.125"/>
      </geometry>
    </collision>
  </link>
  <!-- Joint connecting front left wheel to the main body -->
  <joint name="wheel_joint_front_left" type="continuous">
    <parent link="base_link"/>
    <child link="wheel_link_front_left"/>
    <origin rpy="0 0 1.5708" xyz="0.305 .4 0"/>
    <axis xyz="0 1 0"/>
    <limit effort="10" velocity="5.0"/>
  </joint>
  <joint name="wheel_joint_front_right" type="continuous">
    <parent link="base_link"/>
    <child link="wheel_link_front_right"/>
    <origin rpy="0 0 1.5708" xyz="-0.305 .4 0"/>
    <axis xyz="0 1 0"/>
    <limit effort="10" velocity="5.0"/>
  </joint>
  <joint name="wheel_joint_back_left" type="continuous">
    <parent link="base_link"/>
    <child link="wheel_link_back_left"/>
    <origin rpy="0 0 1.5708" xyz="0.305 -.4 0"/>
    <axis xyz="0 1 0"/>
    <limit effort="10" velocity="5.0"/>
  </joint>
  <joint name="wheel_joint_back_right" type="continuous">
    <parent link="base_link"/>
    <child link="wheel_link_back_right"/>
    <origin rpy="0 0 1.5708" xyz="-0.305 -.4 0"/>
    <axis xyz="0 1 0"/>
    <limit effort="10" velocity="5.0"/>
  </joint>
  <!-- Transmission for wheel_joint_back_right -->
  <transmission name="front_left_wheel_transmission">
    <type>transmission_interface/SimpleTransmission</type>
    <joint name="wheel_joint_front_left">
      <hardwareInterface>hardware_interface/VelocityJointInterface</hardwareInterface>
    </joint>
  </transmission>
  <transmission name="front_right_wheel_transmission">
    <type>transmission_interface/SimpleTransmission</type>
    <joint name="wheel_joint_front_right">
      <hardwareInterface>hardware_interface/VelocityJointInterface</hardwareInterface>
    </joint>
  </transmission>
  <transmission name="back_left_wheel_transmission">
    <type>transmission_interface/SimpleTransmission</type>
    <joint name="wheel_joint_back_left">
      <hardwareInterface>hardware_interface/VelocityJointInterface</hardwareInterface>
    </joint>
  </transmission>
  <transmission name="back_right_wheel_transmission">
    <type>transmission_interface/SimpleTransmission</type>
    <joint name="wheel_joint_back_right">
      <hardwareInterface>hardware_interface/VelocityJointInterface</hardwareInterface>
    </joint>
  </transmission>
</robot>
